Workbook
Name _Toc350567836: 'Năng lượng_2024'!$M$1
Name Slicer_CHỌN_BỮA: #N/A
Name Slicer_Thực_phẩm_cả_ngày: #N/A
Name WW: 'Năng lượng_2024'!$U$10
Name wx: 'Năng lượng_2024'!$AJ$16

Sheet FCDB 2017 (full)
C1: vl1 | D1: vl2 | E1: vl3 | F1: vl4 | G1: vl5 | H1: vl6 | I1: vl7 | J1: vl8 | K1: vl9 | L1: vl10 | M1: vl11 | N1: vl12 | O1: vl13 | P1: vl14 | Q1: vl15 | R1: vl16 | S1: vl17 | T1: vl18 | U1: vl19 | V1: vl20 | W1: vl21 | X1: vl22 | Y1: vl23 | Z1: vl24 | AA1: vl25 | AB1: vl26 | AC1: vl27 | AD1: vl28 | AE1: vl29 | AF1: vl30 | AG1: vl31 | AH1: vl32 | AI1: vl33 | AJ1: vl34 | AK1: vl35 | AL1: vl36 | AM1: vl37 | AN1: vl38 | AO1: vl39 | AP1: vl40 | AQ1: vl41 | AR1: vl42 | AS1: vl43 | AT1: vl44 | AU1: vl45 | AV1: vl46 | AW1: vl47 | AX1: vl48 | AY1: vl49 | AZ1: vl50 | BA1: vl51 | BB1: vl52 | BC1: vl53 | BD1: vl54 | BE1: vl55 | BF1: vl56 | BG1: vl57 | BH1: vl58 | BI1: vl59 | BJ1: vl60 | BK1: vl61 | BL1: vl62 | BM1: vl63 | BN1: vl64 | BO1: vl65 | BP1: vl66 | BQ1: vl67 | BR1: vl68 | BS1: vl69 | BT1: vl70 | BU1: vl71 | BV1: vl72 | BW1: vl73 | BX1: vl74 | BY1: vl75 | BZ1: vl76 | CA1: vl77 | CB1: vl78 | CC1: vl79 | CD1: vl80 | CE1: vl81 | CF1: vl82 | CG1: vl83 | CH1: vl84
A2: TT | B2: Mã số/ code | C2: Tên và mô tả thực phẩm Food name and description | D2: TV/ĐV | E2: Năng lượng (energy, Kcal) | F2: Nước (water) | G2: Protid | H2: Lipid | I2: TS carbohydrate | J2: Chất xơ (crude fiber) | K2: Tro (ash) | L2: Đường tổng (total sugar) | M2: Calcium (Ca) | N2: Photphorous (P) | O2: Iron (Fe) | P2: Vitamin C | Q2: Vitamin B1 | R2: Vitamin B2 | S2: Vitamin PP | T2: Sodium (Na) | U2: Potassium (K) | V2: Magnesium (Mg) | W2: Manganese (Mn) | X2: Zinc (Zn) | Y2: Copper (Cu) | Z2: Selenium (Se) | AA2: Acid pantothenic | AB2: Vitamin B6 | AC2: Folate tổng số | AD2: Acid folic (vitamin B9) | AE2: Biotin (vitamin H) | AF2: Vitamin B12 | AG2: Vitamin A (retinol) | AH2: Retinol | AI2: Vitamin A (RAE) | AJ2: Vitamin D | AK2: Vitamin E | AL2: Vitamin K | AM2: Betacarotene | AN2: Alphacarotene | AO2: Betacryptoxanthin | AP2: Lycopene | AQ2: Lutein + zeaxanthin | AR2: Isoflavone tổng số | AS2: Daidzein | AT2: Genistein | AU2: Glycetin | AV2: Purine | AW2: TS Axit béo no | AX2: Palmitic (C16:0) | AY2: Margaric (C17:0) | AZ2: Stearic (C18:0) | BA2: Arachidic (C20:0) | BB2: Behenic (C22:0) | BC2: Lignoceric (C24:0) | BD2: TS acid béo không no 1 nối đôi | BE2: Myristoleic (C14:1) | BF2: Palmitoleic (C16:1) | BG2: Oleic (C18:1) | BH2: TS acid béo không no nhiều nối đôi | BI2: Linoleic | BJ2: Linolenic | BK2: Arachidonic (C20:4) | BL2: EPA (C20:5 n3) | BM2: DHA (C22:6 n3) | BN2: TS acid béo trans | BO2: Cholesterol | BP2: Phytosterol | BQ2: Lysin | BR2: Methionin | BS2: Tryptophan | BT2: Phenylalanin | BU2: Threonin | BV2: Valine | BW2: Leucine | BX2: Isoleucine | BY2: Arginine | BZ2: Histidine | CA2: Cystine | CB2: Tyrosine | CC2: Alanine | CD2: Aspartic acid | CE2: Glutamic acid | CF2: Glycine | CG2: Proline | CH2: Serine
C3: Tiếng Việt | E3: Kcal | F3: g | G3: g | H3: g | I3: g | J3: g | K3: g | L3: g | M3: mg | N3: mg | O3: mg | P3: mg | Q3: mg | R3: mg | S3: mg | T3: mg | U3: mg | V3: mg | W3: mg | X3: mg | Y3: (mcg) | Z3: (mcg) | AA3: mg | AB3: mg | AC3: mcg | AD3: mcg | AE3: mcg | AF3: mcg | AG3: mcg | AH3: IU | AI3: mcg | AJ3: mcg | AK3: mg | AL3: mcg | AM3: mcg | AN3: mcg | AO3: mcg | AP3: mcg | AQ3: mcg | AR3: mg | AS3: mg | AT3: mg | AU3: mg | AV3: mg | AW3: g | AX3: g | AY3: g | AZ3: g | BA3: g | BB3: g | BC3: g | BD3: g | BE3: g | BF3: g | BG3: g | BI3: g | BJ3: g | BO3: (mg) | BP3: mg | BQ3: mg | BR3: mg | BS3: mg | BT3: mg | BU3: mg | BV3: mg | BW3: mg | BX3: mg | BY3: mg | BZ3: mg | CA3: mg | CB3: mg | CC3: mg | CD3: mg | CE3: mg | CF3: mg | CG3: mg | CH3: mg
A5: I | C5: Ngũ cốc và sản phẩm chế biến
A6: 1 | B6: 1001 | C6: Gạo nếp cái | D6: TV | E6: =G6*4+H6*9+I6*4 -> 348.3 | F6: 14 | G6: 8.6 | H6: 1.5 | I6: =100-SUM(F6,G6,H6,K6) -> 75.1 | J6: 0.6 | K6: 0.8 | M6: 32 | N6: 98 | O6: 1.2 | P6: 0 | Q6: 0.14 | R6: 0.06 | S6: 2.4 | T6: 3 | U6: 282 | V6: 17 | W6: 1.1 | X6: 2.2 | Y6: 280 | AG6: 0 | AH6: =AG6*3.33 -> 0 | AI6: =AG6+AM6/12+AN6/24+AO6/24 -> 0 | AM6: 0 | AN6: 0 | AO6: 0 | AP6: 0 | AQ6: 0 | BO6: 0 | BQ6: 207 | BR6: 66 | BT6: 229 | BU6: 177 | BV6: 317 | BW6: 531 | BX6: 222 | BY6: 435 | BZ6: 133 | CA6: 96 | CB6: 111 | CC6: 347 | CD6: 443 | CE6: 1210 | CF6: 281 | CG6: 376 | CH6: 309
A7: 2 | B7: 1002 | C7: Gạo nếp (loại thường) | D7: TV | E7: =G7*4+H7*9+I7*4 -> 349.6 | F7: 13.9 | G7: 8.4 | H7: 1.6 | I7: =100-SUM(F7,G7,H7,K7) -> 75.4 | J7: 0.5 | K7: 0.7 | M7: 16 | N7: 130 | O7: 1.2 | P7: 0 | Q7: 0.16 | R7: 0.06 | S7: 2.4 | T7: 3 | U7: 282 | V7: 17 | W7: 1.1 | X7: 2.2 | Y7: 280 | Z7: 15.1 | AA7: 0.284 | AB7: 0.107 | AC7: 7 | AD7: 0 | AF7: 0 | AG7: 0 | AH7: =AG7*3.33 -> 0 | AI7: =AG7+AM7/12+AN7/24+AO7/24 -> 0 | AM7: 0 | AN7: 0 | AO7: 0 | AP7: 0 | AQ7: 0 | AW7: 0.111 | AX7: 0.094 | AY7: 0 | AZ7: 0.01 | BA7: 0 | BB7: 0 | BC7: 0 | BD7: 0.2 | BE7: 0 | BF7: 0.002 | BG7: 0.198 | BH7: 0.198 | BI7: 0.189 | BJ7: 0.008 | BK7: 0 | BL7: 0 | BM7: 0 | BO7: 0 | BQ7: 246 | BR7: 160 | BS7: 79 | BT7: 364 | BU7: 244 | BV7: 416 | BW7: 563 | BX7: 294 | BY7: 568 | BZ7: 160 | CA7: 140 | CB7: 228 | CC7: 395 | CD7: 640 | CE7: 1328 | CF7: 310 | CG7: 321 | CH7: 358
A8: 3 | B8: 1003 | C8: Gạo tẻ giã | D8: TV | E8: =G8*4+H8*9+I8*4 -> 346.9 | F8: 14 | G8: 8.1 | H8: 1.3 | I8: =100-SUM(F8,G8,H8,K8) -> 75.7 | J8: 0.7 | K8: 0.9 | M8: 36 | N8: 108 | O8: 0.2 | P8: 0 | Q8: 0.12 | R8: 0.04 | S8: 1.9 | T8: 5 | U8: 202 | V8: 52 | W8: 1.5 | X8: 1.9 | Y8: 360 | Z8: 38.8 | AE8: 3 | AG8: 0 | AH8: =AG8*3.33 -> 0 | AI8: =AG8+AM8/12+AN8/24+AO8/24 -> 0 | AM8: 0 | AN8: 0 | AO8: 0 | AP8: 0 | AQ8: 0 | AW8: 0.35413793 | AX8: 0.31603448 | AY8: 0 | AZ8: 0.024655172 | BA8: 0 | BB8: 0 | BC8: 0 | BD8: 0.40568966 | BE8: 0 | BF8: 0.0044827586 | BG8: 0.4012069 | BH8: 0.34741379 | BI8: 0.28689655 | BJ8: 0.060517241 | BK8: 0 | BL8: 0 | BM8: 0 | BO8: 0 | BQ8: 245.05063 | BR8: 158.92405 | BS8: 78.949367 | BT8: 361.93671 | BU8: 241.97468 | BV8: 413.20253 | BW8: 559.82278 | BX8: 292.21519 | BY8: 564.94937 | BZ8: 158.92405 | CA8: 138.41772 | CB8: 226.59494 | CC8: 392.6962 | CD8: 636.72152 | CE8: 1320.6076 | CF8: 308.62025 | CG8: 318.87342 | CH8: 355.78481
A9: 4 | B9: 1004 | C9: Gạo tẻ máy | D9: TV | E9: =G9*4+H9*9+I9*4 -> 345.8 | F9: 14 | G9: 7.9 | H9: 1 | I9: =100-SUM(F9,G9,H9,K9) -> 76.3 | J9: 0.4 | K9: 0.8 | M9: 30 | N9: 104 | O9: 1.3 | P9: 0 | Q9: 0.1 | R9: 0.03 | S9: 1.6 | T9: 5 | U9: 241 | V9: 14 | W9: 0.9 | X9: 1.5 | Y9: 230 | Z9: 31.8 | AA9: 1.342 | AB9: 0.145 | AC9: 9 | AD9: 0 | AE9: 3 | AF9: 0 | AG9: 0 | AH9: =AG9*3.33 -> 0 | AI9: =AG9+AM9/12+AN9/24+AO9/24 -> 0 | AM9: 0 | AN9: 0 | AO9: 0 | AP9: 0 | AQ9: 0 | AW9: 0.158 | AX9: 0.141 | AY9: 0 | AZ9: 0.011 | BA9: 0 | BB9: 0 | BC9: 0 | BD9: 0.181 | BE9: 0 | BF9: 0.002 | BG9: 0.179 | BH9: 0.155 | BI9: 0.128 | BJ9: 0.027 | BK9: 0 | BL9: 0 | BM9: 0 | BO9: 0 | BQ9: 239 | BR9: 155 | BS9: 77 | BT9: 353 | BU9: 236 | BV9: 403 | BW9: 546 | BX9: 285 | BY9: 551 | BZ9: 155 | CA9: 135 | CB9: 221 | CC9: 383 | CD9: 621 | CE9: 1288 | CF9: 301 | CG9: 311 | CH9: 347
A10: 5 | B10: 1005 | C10: Gạo lứt | D10: TV | E10: =G10*4+H10*9+I10*4 -> 358.84 | F10: 12.37 | G10: 7.5 | H10: 2.68 | I10: =100-SUM(F10,G10,H10,K10) -> 76.18 | J10: 3.4 | K10: 1.27 | M10: 16 | N10: 246 | O10: 2.8 | P10: 0 | Q10: 0.34 | R10: 0.07 | S10: 5 | T10: 5 | U10: 202 | V10: 52 | W10: 1.5 | X10: 1.9 | Y10: 360 | Z10: 38.8 | AA10: 1.5 | AB10: 0.62 | AC10: 20 | AD10: 0 | AG10: 0 | AH10: =AG10*3.33 -> 0 | AI10: =AG10+AM10/12+AN10/24+AO10/24 -> 0 | AM10: 0 | AN10: 0 | AO10: 0 | AP10: 0 | AQ10: 0 | AW10: 0.536 | AX10: 0.457 | AY10: 0 | AZ10: 0.048 | BA10: 0 | BB10: 0 | BC10: 0 | BD10: 0.971 | BE10: 0 | BF10: 0.01 | BG10: 0.961 | BH10: 0.959 | BI10: 0.918 | BJ10: 0.041 | BK10: 0 | BL10: 0 | BM10: 0 | BO10: 0 | BQ10: 286 | BR10: 169 | BS10: 96 | BT10: 387 | BU10: 275 | BV10: 440 | BW10: 620 | BX10: 318 | BY10: 569 | BZ10: 190 | CA10: 91 | CB10: 281 | CC10: 437 | CD10: 702 | CE10: 1528 | CF10: 369 | CG10: 352 | CH10: 388
A11: 6 | B11: 1006 | C11: Kê | D11: TV | E11: =G11*4+H11*9+I11*4 -> 344.6 | F11: 14 | G11: 7 | H11: 3 | I11: =100-SUM(F11,G11,H11,K11) -> 72.4 | J11: 3.4 | K11: 3.6 | M11: 22 | N11: 290 | O11: 2.7 | P11: 0 | Q11: 0.4 | R11: 0.09 | S11: 1.6 | T11: 7 | U11: 249 | V11: 430 | W11: 1.7 | X11: 1.5 | Y11: 440 | Z11: 2.7 | AA11: 0.848 | AB11: 0.384 | AC11: 85 | AD11: 0 | AF11: 0 | AG11: 0 | AH11: =AG11*3.33 -> 0 | AI11: =AG11+AM11/12+AN11/24+AO11/24 -> 5 | AK11: 0.05 | AL11: 0.9 | AM11: 60 | AV11: 62 | AW11: 0.723 | AX11: 0.528 | AY11: 0 | AZ11: 0.154 | BA11: 0 | BB11: 0 | BC11: 0 | BD11: 0.773 | BE11: 0 | BF11: 0.014 | BG11: 0.739 | BH11: 2.134 | BI11: 2.015 | BJ11: 0.118 | BK11: 0 | BL11: 0 | BM11: 0 | BO11: 0 | BQ11: 212 | BR11: 221 | BS11: 119 | BT11: 580 | BU11: 353 | BV11: 578 | BW11: 1400 | BX11: 465 | BY11: 382 | BZ11: 236 | CA11: 212 | CB11: 340 | CC11: 986 | CD11: 726 | CE11: 2396 | CF11: 287 | CG11: 877 | CH11: 644
A12: 7 | B12: 1007 | C12: Ngô bắp tươi | D12: TV | E12: =G12*4+H12*9+I12*4 -> 200.3 | F12: 52 | G12: 4.1 | H12: 2.3 | I12: =100-SUM(F12,G12,H12,K12) -> 40.8 | J12: 1.2 | K12: 0.8 | L12: 1.7 | M12: 20 | N12: 187 | O12: 1.5 | P12: 12 | Q12: 0.15 | R12: 0.08 | S12: 1.8 | T12: 3 | U12: 306 | V12: 39 | W12: 0.35 | X12: 1.4 | Y12: 240 | Z12: 4 | AA12: 0.54 | AB12: 0.16 | AC12: 33 | AD12: 0 | AE12: 0.5 | AF12: 0 | AG12: 0 | AH12: =AG12*3.33 -> 0 | AI12: =AG12+AM12/12+AN12/24+AO12/24 -> 20 | AK12: 0.8 | AL12: 0 | AM12: 240 | AV12: 52 | AW12: 0.28 | AX12: 0.24 | AY12: 0 | AZ12: 0.037 | BA12: 0 | BB12: 0 | BC12: 0 | BD12: 0.52 | BE12: 0 | BF12: 0 | BG12: 0.52 | BH12: 0.89 | BI12: 0.86 | BJ12: 0.03 | BK12: 0 | BL12: 0 | BM12: 0 | BO12: 0 | BQ12: 100 | BR12: 71 | BS12: 24 | BT12: 190 | BU12: 140 | BV12: 180 | BW12: 470 | BX12: 140 | BY12: 150 | BZ12: 100 | CA12: 59 | CB12: 140 | CC12: 280 | CD12: 240 | CE12: 760 | CF12: 140 | CG12: 330 | CH12: 190
A13: 8 | B13: 1008 | C13: Ngô vàng hạt khô | D13: TV | E13: =G13*4+H13*9+I13*4 -> 362.3 | F13: 14 | G13: 8.6 | H13: 4.7 | I13: =100-SUM(F13,G13,H13,K13) -> 71.4 | J13: 2 | K13: 1.3 | L13: 0.64 | M13: 30 | N13: 190 | O13: 2.3 | P13: 0 | Q13: 0.28 | R13: 0.11 | S13: 2 | T13: 35 | U13: 287 | V13: 127 | W13: 0.485 | X13: 2.21 | Y13: 314 | Z13: 15.5 | AA13: 0.424 | AB13: 0.622 | AC13: 19 | AD13: 0 | AF13: 0 | AG13: 0 | AH13: =AG13*3.33 -> 0 | AI13: =AG13+AM13/12+AN13/24+AO13/24 -> 10.708333 | AK13: 0.49 | AL13: 0.3 | AM13: 97 | AN13: 63 | AO13: 0 | AP13: 0 | AQ13: 1355 | AW13: 0.667 | AX13: 0.569 | AY13: 0 | AZ13: 0.075 | BA13: 0 | BB13: 0 | BC13: 0 | BD13: 1.251 | BE13: 0 | BF13: 0.004 | BG13: 1.247 | BH13: 2.163 | BI13: 2.097 | BJ13: 0.065 | BK13: 0 | BL13: 0 | BM13: 0 | BO13: 0 | BQ13: 265 | BR13: 197 | BS13: 67 | BT13: 463 | BU13: 354 | BV13: 477 | BW13: 1155 | BX13: 337 | BY13: 470 | BZ13: 287 | CA13: 170 | CB13: 383 | CC13: 705 | CD13: 655 | CE13: 1768 | CF13: 386 | CG13: 822 | CH13: 447
A14: 9 | B14: 1009 | C14: Bánh bao | E14: =G14*4+H14*9+I14*4 -> 276 | F14: 43.2 | G14: 10.4 | H14: 10.8 | I14: =100-SUM(F14,G14,H14,K14) -> 34.3 | J14: 0.86 | K14: 1.3 | M14: 72.42 | N14: 67.44 | O14: 0.76 | Q14: 0.1 | R14: 0.04 | S14: 1 | X14: 1.33 | AG14: 0 | AH14: =AG14*3.33 -> 0 | AI14: =AG14+AM14/12+AN14/24+AO14/24 -> 0 | AM14: 0 | AN14: 0 | AO14: 0 | AP14: 0 | AQ14: 0 | BO14: 0
A15: 10 | B15: 1010 | C15: Bánh đa nem | D15: TV | E15: =G15*4+H15*9+I15*4 -> 335.4 | F15: 15 | G15: 4 | H15: 0.2 | I15: =100-SUM(F15,G15,H15,K15) -> 79.4 | J15: 0.5 | K15: 1.4 | M15: 20 | N15: 65 | O15: 0.3 | P15: 0 | AG15: 0 | AH15: =AG15*3.33 -> 0 | AI15: =AG15+AM15/12+AN15/24+AO15/24 -> 0 | AM15: 0 | AN15: 0 | AO15: 0 | AP15: 0 | AQ15: 0 | BO15: 0
A16: 11 | B16: 1011 | C16: Bánh đúc | D16: TV | E16: =G16*4+H16*9+I16*4 -> 51.9 | F16: 86.8 | G16: 0.9 | H16: 0.3 | I16: =100-SUM(F16,G16,H16,K16) -> 11.4 | J16: 0.1 | K16: 0.6 | M16: 50 | N16: 19 | O16: 0.4 | P16: 0 | AG16: 0 | AH16: =AG16*3.33 -> 0 | AI16: =AG16+AM16/12+AN16/24+AO16/24 -> 0 | AM16: 0 | AN16: 0 | AO16: 0 | AP16: 0 | AQ16: 0 | BO16: 0
A17: 12 | B17: 1012 | C17: Bánh mỳ | D17: TV | E17: =G17*4+H17*9+I17*4 -> 250 | F17: 37.2 | G17: 7.9 | H17: 0.8 | I17: =100-SUM(F17,G17,H17,K17) -> 52.8 | J17: 0.2 | K17: 1.3 | M17: 28 | N17: 164 | O17: 2 | P17: 0 | Q17: 0.1 | R17: 0.07 | S17: 0.7 | AG17: 0 | AH17: =AG17*3.33 -> 0 | AI17: =AG17+AM17/12+AN17/24+AO17/24 -> 0 | AM17: 0 | AN17: 0 | AO17: 0 | AP17: 0 | AQ17: 0 | BO17: 0 | BQ17: 163 | BR17: 133 | BS17: 66 | BT17: 314 | BU17: 216 | BV17: 366 | BW17: 460 | BX17: 294 | BY17: 294 | BZ17: 133 | CA17: 188 | CB17: 208 | CC17: 280 | CD17: 392 | CE17: 1924 | CF17: 331 | CG17: 732 | CH17: 345
A18: 13 | B18: 1013 | C18: Bánh phở | D18: TV | E18: =G18*4+H18*9+I18*4 -> 141.2 | F18: 64.3 | G18: 3.2 | I18: =100-SUM(F18,G18,H18,K18) -> 32.1 | K18: 0.4 | M18: 16 | N18: 64 | O18: 0.3 | P18: 0 | Q18: 0.01 | R18: 0.01 | S18: 0.2 | T18: 3 | U18: 15 | AG18: 0 | AH18: =AG18*3.33 -> 0 | AI18: =AG18+AM18/12+AN18/24+AO18/24 -> 0 | AM18: 0 | AN18: 0 | AO18: 0 | AP18: 0 | AQ18: 0 | BO18: 0
A19: 14 | B19: 1014 | C19: Bánh quẩy nóng | D19: TV | E19: =G19*4+H19*9+I19*4 -> 200.4 | F19: 57.6 | G19: 3.7 | H19: 6.8 | I19: =100-SUM(F19,G19,H19,K19) -> 31.1 | J19: 0.152513 | K19: 0.8 | M19: 47.9 | N19: 18.94 | O19: 0.94 | P19: 0 | X19: 0.27 | AG19: 0 | AH19: =AG19*3.33 -> 0 | AI19: =AG19+AM19/12+AN19/24+AO19/24 -> 0 | AM19: 0 | AN19: 0 | AO19: 0 | AP19: 0 | AQ19: 0 | BO19: 0
A20: 15 | B20: 1015 | C20: Bỏng ngô | D20: TV | E20: =G20*4+H20*9+I20*4 -> 385.6 | F20: 3 | G20: 8.6 | H20: 1.6 | I20: =100-SUM(F20,G20,H20,K20) -> 84.2 | J20: 3.4 | K20: 2.6 | M20: 3 | N20: 47 | O20: 0.6 | P20: 0 | Q20: 0.02 | R20: 0.03 | S20: 0.6 | T20: 346 | U20: 609 | V20: 334 | AG20: 0 | AH20: =AG20*3.33 -> 0 | AI20: =AG20+AM20/12+AN20/24+AO20/24 -> 0 | AM20: 0 | AN20: 0 | AO20: 0 | AP20: 0 | AQ20: 0 | BO20: 0 | BQ20: 230 | BR20: 166 | BS20: 61 | BT20: 421 | BU20: 310 | BV20: 418 | BW20: 1081 | BX20: 316 | BY20: 362 | BZ20: 235 | CA20: 134 | CB20: 330 | CC20: 650 | CD20: 541 | CE20: 1634 | CF20: 319 | CG20: 771 | CH20: 429
A21: 16 | B21: 1016 | C21: Bột gạo nếp | D21: TV | E21: =G21*4+H21*9+I21*4 -> 364.8 | F21: 10 | G21: 8.2 | H21: 1.6 | I21: =100-SUM(F21,G21,H21,K21) -> 79.4 | J21: 0.6 | K21: 0.8 | M21: 12 | N21: 148 | O21: 0.8 | P21: 0 | Q21: 0.1 | R21: 0.02 | S21: 1.7 | T21: 3.1177829 | U21: 293.07159 | V21: 17.667436 | W21: 1.1431871 | X21: 2.2863741 | Y21: 290.99307 | Z21: 15.692841 | AA21: 0.29515012 | AB21: 0.11120092 | AC21: 7.2748268 | AD21: 0 | AF21: 0 | AG21: 0 | AH21: =AG21*3.33 -> 0 | AI21: =AG21+AM21/12+AN21/24+AO21/24 -> 0 | AM21: 0 | AN21: 0 | AO21: 0 | AP21: 0 | AQ21: 0 | AW21: 0.10835714 | AX21: 0.091761905 | AY21: 0 | AZ21: 0.0097619048 | BA21: 0 | BB21: 0 | BC21: 0 | BD21: 0.1952381 | BE21: 0 | BF21: 0.001952381 | BG21: 0.19328571 | BH21: 0.19328571 | BI21: 0.1845 | BJ21: 0.0078095238 | BK21: 0 | BL21: 0 | BM21: 0 | BO21: 0 | BQ21: 240.14286 | BR21: 156.19048 | BS21: 77.119048 | BT21: 355.33333 | BU21: 238.19048 | BV21: 406.09524 | BW21: 549.59524 | BX21: 287 | BY21: 554.47619 | BZ21: 156.19048 | CA21: 136.66667 | CB21: 222.57143 | CC21: 385.59524 | CD21: 624.7619 | CE21: 1296.381 | CF21: 302.61905 | CG21: 313.35714 | CH21: 349.47619
A22: 17 | B22: 1017 | C22: Bột gạo tẻ | D22: TV | E22: =G22*4+H22*9+I22*4 -> 360.4 | F22: 10 | G22: 6.6 | H22: 0.4 | I22: =100-SUM(F22,G22,H22,K22) -> 82.6 | J22: 0.4 | K22: 0.4 | M22: 24 | N22: 135 | O22: 1.9 | P22: 0 | Q22: 0.08 | R22: 0.05 | S22: 2.1 | T22: 0 | U22: 76 | V22: 35 | W22: 1.2 | X22: 0.8 | Y22: 130 | Z22: 15.1 | AA22: 0.819 | AB22: 0.436 | AC22: 4 | AD22: 0 | AE22: 1 | AF22: 0 | AG22: 0 | AH22: =AG22*3.33 -> 0 | AI22: =AG22+AM22/12+AN22/24+AO22/24 -> 0 | AK22: 0.11 | AL22: 0 | AM22: 0 | AN22: 0 | AO22: 0 | AP22: 0 | AQ22: 0 | AW22: 0.386 | AX22: 0.345 | AY22: 0 | AZ22: 0.026 | BA22: 0 | BB22: 0 | BC22: 0 | BD22: 0.442 | BE22: 0 | BF22: 0.005 | BG22: 0.436 | BH22: 0.379 | BI22: 0.313 | BJ22: 0.067 | BK22: 0 | BL22: 0 | BM22: 0 | BO22: 0 | BQ22: 207 | BR22: 144 | BS22: 72 | BT22: 317 | BU22: 210 | BV22: 348 | BW22: 488 | BX22: 244 | BY22: 516 | BZ22: 149 | CA22: 107 | CB22: 314 | CC22: 332 | CD22: 549 | CE22: 1097 | CF22: 267 | CG22: 278 | CH22: 310
A23: 18 | B23: 1018 | C23: Bột mì | D23: TV | E23: =G23*4+H23*9+I23*4 -> 346.7 | F23: 14 | G23: 11 | H23: 1.1 | I23: =100-SUM(F23,G23,H23,K23) -> 73.2 | J23: 0.3 | K23: 0.7 | M23: 29 | N23: 132 | O23: 2 | P23: 0 | Q23: 0.18 | R23: 0.13 | S23: 1 | T23: 4 | U23: 186 | V23: 173 | W23: 2 | X23: 2.5 | Y23: 21 | Z23: 28 | AA23: 1.008 | AB23: 0.341 | AC23: 44 | AD23: 0 | AE23: 1.9 | AF23: 0 | AG23: 0 | AH23: =AG23*3.33 -> 0 | AI23: =AG23+AM23/12+AN23/24+AO23/24 -> 0 | AK23: 0.82 | AL23: 1.9 | AM23: 0 | AN23: 0 | AO23: 0 | AP23: 0 | AQ23: 0 | AV23: 14 | AW23: 0.322 | AX23: 0.271 | AY23: 0 | AZ23: 0.015 | BA23: 0 | BB23: 0 | BC23: 0 | BD23: 0.232 | BE23: 0 | BF23: 0.013 | BG23: 0.219 | BH23: 0.779 | BI23: 0.738 | BJ23: 0.038 | BK23: 0.002 | BL23: 0 | BM23: 0 | BO23: 0 | BQ23: 340 | BR23: 140 | BS23: 110 | BT23: 630 | BU23: 380 | BV23: 520 | BW23: 780 | BX23: 380 | BY23: 320 | BZ23: 170 | CA23: 265 | CB23: 142 | CC23: 278 | CD23: 329 | CE23: 3480 | CF23: 341 | CG23: 1254 | CH23: 449
A24: 19 | B24: 1019 | C24: Bột ngô vàng | D24: TV | E24: =G24*4+H24*9+I24*4 -> 367.2 | F24: 12 | G24: 8.3 | H24: 4 | I24: =100-SUM(F24,G24,H24,K24) -> 74.5 | J24: 1.5 | K24: 1.2 | M24: 15 | N24: 170 | O24: 2.1 | P24: 0 | Q24: 0.17 | R24: 0.08 | S24: 1.9 | T24: 5 | U24: 315 | V24: 93 | W24: 0.46 | X24: 1.73 | Y24: 230 | Z24: 15.4 | AA24: 0.658 | AB24: 0.37 | AC24: 25 | AD24: 0 | AF24: 0 | AG24: 0 | AH24: =AG24*3.33 -> 0 | AI24: =AG24+AM24/12+AN24/24+AO24/24 -> 10.708333 | AK24: 0.42 | AL24: 0.3 | AM24: 97 | AN24: 63 | AO24: 0 | AP24: 0 | AQ24: 1355 | AW24: 0.543 | AX24: 0.463 | AY24: 0 | AZ24: 0.061 | BA24: 0 | BB24: 0 | BC24: 0 | BD24: 1.018 | BE24: 0 | BF24: 0.003 | BG24: 1.015 | BH24: 1.759 | BI24: 1.706 | BJ24: 0.053 | BK24: 0 | BL24: 0 | BM24: 0 | BO24: 0 | BQ24: 195 | BR24: 145 | BS24: 49 | BT24: 340 | BU24: 261 | BV24: 351 | BW24: 850 | BX24: 248 | BY24: 345 | BZ24: 211 | CA24: 125 | CB24: 282 | CC24: 518 | CD24: 482 | CE24: 1300 | CF24: 284 | CG24: 605 | CH24: 329
A25: 20 | B25: 1020 | C25: Bún | D25: TV | E25: =G25*4+H25*9+I25*4 -> 111.6 | F25: 72 | G25: 1.7 | I25: =100-SUM(F25,G25,H25,K25) -> 26.2 | J25: 0.5 | K25: 0.1 | M25: 12 | N25: 32 | O25: 0.2 | P25: 0 | Q25: 0.04 | R25: 0.01 | S25: 0.08 | AG25: 0 | AH25: =AG25*3.33 -> 0 | AI25: =AG25+AM25/12+AN25/24+AO25/24 -> 0 | AM25: 0 | AN25: 0 | AO25: 0 | AP25: 0 | AQ25: 0 | BO25: 0
A26: 21 | B26: 1021 | C26: Cốm tươi | D26: TV | E26: =G26*4+H26*9+I26*4 -> 306.9 | F26: 24.4 | G26: 4.4 | H26: 1.7 | I26: =100-SUM(F26,G26,H26,K26) -> 68.5 | J26: 0.6 | K26: 1 | M26: 19.6 | N26: 422.7 | O26: 2 | X26: 1.83 | AG26: 0 | AH26: =AG26*3.33 -> 0 | AI26: =AG26+AM26/12+AN26/24+AO26/24 -> 0 | AM26: 0 | AN26: 0 | AO26: 0 | AP26: 0 | AQ26: 0 | BO26: 0
A27: 22 | B27: 1022 | C27: Mỳ sợi | D27: TV | E27: =G27*4+H27*9+I27*4 -> 350.1 | F27: 13 | G27: 11 | H27: 0.9 | I27: =100-SUM(F27,G27,H27,K27) -> 74.5 | J27: 0.3 | K27: 0.6 | M27: 34 | N27: 97 | O27: 1.5 | P27: 0 | Q27: 0.1 | R27: 0.04 | S27: 1.1 | AC27: 13 | AG27: 0 | AH27: =AG27*3.33 -> 0 | AI27: =AG27+AM27/12+AN27/24+AO27/24 -> 0 | AM27: 0 | AN27: 0 | AO27: 0 | AP27: 0 | AQ27: 0 | BO27: 0 | BQ27: 432 | BR27: 320 | BS27: 150 | BT27: 702 | BU27: 490 | BV27: 808 | BW27: 1036 | BX27: 667 | BY27: 679 | BZ27: 300
A28: 23 | B28: 1023 | C28: Ngô nếp luộc | D28: TV | E28: =G28*4+H28*9+I28*4 -> 171.8 | F28: 59 | G28: 3.9 | H28: 2.2 | I28: =100-SUM(F28,G28,H28,K28) -> 34.1 | J28: 1.2 | K28: 0.8 | M28: 18 | N28: 146 | O28: 0.8 | P28: 0 | AG28: 0 | AH28: =AG28*3.33 -> 0 | AI28: =AG28+AM28/12+AN28/24+AO28/24 -> 0 | AM28: 0 | AN28: 0 | AO28: 0 | AP28: 0 | AQ28: 0 | BO28: 0
A29: 24 | B29: 1024 | C29: Mỳ ăn liền (mỳ tôm) | D29: TV | E29: =G29*4+H29*9+I29*4 -> 456 | F29: 4.3 | G29: 10.5 | H29: 20.4 | I29: =100-SUM(F29,G29,H29,K29) -> 57.6 | J29: 4.1 | K29: 7.2 | M29: 27 | N29: 120 | O29: 0.9 | P29: 0 | Q29: 0.22 | R29: 0.07 | S29: 1.5 | T29: 1975 | U29: 130 | AH29: 0 | AI29: =AG29+AM29/12+AN29/24+AO29/24 -> 0.66666667 | AM29: 8
A31: II | C31: Khoai củ và sản phẩm chế biến
A32: 25 | B32: 2001 | C32: Củ ấu | D32: TV | E32: =G32*4+H32*9+I32*4 -> 159.7 | F32: 59 | G32: 3.6 | H32: 0.5 | I32: =100-SUM(F32,G32,H32,K32) -> 35.2 | J32: 1 | K32: 1.7 | M32: 9 | N32: 49 | O32: 0.7 | P32: 5 | Q32: 0.23 | R32: 0.05 | S32: 1.9 | AG32: 0 | AH32: =AG32*3.33 -> 0 | AI32: =AG32+AM32/12+AN32/24+AO32/24 -> 0.41666667 | AM32: 5 | BO32: 0
A33: 26 | B33: 2002 | C33: Củ cái | D33: TV | E33: =G33*4+H33*9+I33*4 -> 133.6 | F33: 65.5 | G33: 3.1 | I33: =100-SUM(F33,G33,H33,K33) -> 30.3 | J33: 1.8 | K33: 1.1 | M33: 20 | N33: 32 | O33: 2.9 | P33: 1 | T33: 12 | U33: 397 | V33: 20 | X33: 11 | AA33: 0.314 | AB33: 0.293 | AC33: 23 | AD33: 0 | AF33: 0 | AG33: 0 | AH33: =AG33*3.33 -> 0 | AI33: =AG33+AM33/12+AN33/24+AO33/24 -> 6.9166667 | AK33: 0.39 | AL33: 2.6 | AM33: 83 | AW33: 0.037 | AX33: 0.034 | AY33: 0 | AZ33: 0.004 | BA33: 0 | BB33: 0 | BC33: 0 | BD33: 0.006 | BE33: 0 | BF33: 0 | BG33: 0.006 | BH33: 0.076 | BI33: 0.064 | BJ33: 0.012 | BK33: 0 | BL33: 0 | BM33: 0 | BO33: 0 | BQ33: 59 | BR33: 21 | BS33: 12 | BT33: 71 | BU33: 54 | BV33: 62 | BW33: 96 | BX33: 52 | BY33: 127 | BZ33: 34 | CA33: 19 | CB33: 40 | CC33: 63 | CD33: 155 | CE33: 181 | CF33: 53 | CG33: 54 | CH33: 81
A34: 27 | B34: 2003 | C34: Củ dong | D34: TV | E34: =G34*4+H34*9+I34*4 -> 128.8 | F34: 66.5 | G34: 1.4 | I34: =100-SUM(F34,G34,H34,K34) -> 30.8 | J34: 2.4 | K34: 1.3 | M34: 42 | N34: 21 | T34: 73 | U34: 299 | V34: 46 | AG34: 0 | AH34: =AG34*3.33 -> 0 | AI34: =AG34+AM34/12+AN34/24+AO34/24 -> 0 | AM34: 0 | AN34: 0 | AO34: 0 | AP34: 0 | AQ34: 0 | BO34: 0
A35: 28 | B35: 2004 | C35: Củ sắn | D35: TV | E35: =G35*4+H35*9+I35*4 -> 157.8 | F35: 60 | G35: 1.1 | H35: 0.2 | I35: =100-SUM(F35,G35,H35,K35) -> 37.9 | J35: 1.5 | K35: 0.8 | M35: 25 | N35: 30 | O35: 1.2 | P35: 34 | Q35: 0.03 | R35: 0.03 | S35: 0.6 | T35: 2 | U35: 394 | V35: 4 | AA35: 0.107 | AB35: 0.088 | AC35: 27 | AD35: 0 | AF35: 0 | AG35: 0 | AH35: =AG35*3.33 -> 0 | AI35: =AG35+AM35/12+AN35/24+AO35/24 -> 0.66666667 | AK35: 0.19 | AL35: 1.9 | AM35: 8 | AN35: 0 | AO35: 0 | AP35: 0 | AQ35: 0 | AW35: 0.074 | AX35: 0.069 | AY35: 0 | AZ35: 0.005 | BA35: 0 | BB35: 0 | BC35: 0 | BD35: 0.075 | BE35: 0 | BF35: 0 | BG35: 0.075 | BH35: 0.048 | BI35: 0.032 | BJ35: 0.017 | BK35: 0 | BL35: 0 | BM35: 0 | BO35: 0 | BQ35: 44 | BR35: 11 | BS35: 19 | BT35: 26 | BU35: 28 | BV35: 35 | BW35: 39 | BX35: 27 | BY35: 137 | BZ35: 20 | CA35: 28 | CB35: 17 | CC35: 38 | CD35: 79 | CE35: 206 | CF35: 28 | CG35: 33 | CH35: 33
A36: 29 | B36: 2005 | C36: Củ sắn dây | D36: TV | E36: =G36*4+H36*9+I36*4 -> 156.1 | F36: 60.3 | G36: 1.6 | H36: 0.1 | I36: =100-SUM(F36,G36,H36,K36) -> 37.2 | J36: 9.2 | K36: 0.8 | M36: 28 | N36: 45 | O36: 0.2 | AG36: 0 | AH36: =AG36*3.33 -> 0 | AI36: =AG36+AM36/12+AN36/24+AO36/24 -> 0 | AM36: 0 | AN36: 0 | AO36: 0 | AP36: 0 | AQ36: 0 | BO36: 0
A37: 30 | B37: 2006 | C37: Củ súng khô (đã bỏ vỏ) | D37: TV | E37: =G37*4+H37*9+I37*4 -> 359.3 | F37: 8.6 | G37: 16.1 | H37: 0.5 | I37: =100-SUM(F37,G37,H37,K37) -> 72.6 | J37: 2.3 | K37: 2.2 | M37: 100 | N37: 720 | O37: 0.2 | AG37: 0 | AH37: =AG37*3.33 -> 0 | AI37: =AG37+AM37/12+AN37/24+AO37/24 -> 0 | AM37: 0 | AN37: 0 | AO37: 0 | AP37: 0 | AQ37: 0 | BO37: 0
A38: 31 | B38: 2007 | C38: Củ từ | D38: TV | E38: =G38*4+H38*9+I38*4 -> 96.8 | F38: 75 | G38: 1.5 | I38: =100-SUM(F38,G38,H38,K38) -> 22.7 | J38: 1.2 | K38: 0.8 | M38: 28 | N38: 30 | O38: 0.2 | P38: 2 | T38: 71 | U38: 264 | V38: 28 | AG38: 0 | AH38: =AG38*3.33 -> 0 | AI38: =AG38+AM38/12+AN38/24+AO38/24 -> 0 | AM38: 0 | AN38: 0 | AO38: 0 | AP38: 0 | AQ38: 0 | BO38: 0
A39: 32 | B39: 2008 | C39: Khoai lang | D39: TV | E39: =G39*4+H39*9+I39*4 -> 124.2 | F39: 68 | G39: 0.8 | H39: 0.2 | I39: =100-SUM(F39,G39,H39,K39) -> 29.8 | J39: 1.3 | K39: 1.2 | M39: 34 | N39: 49.4 | O39: 1 | P39: 23 | Q39: 0.05 | R39: 0.05 | S39: 0.6 | T39: 31 | U39: 210 | V39: 201 | W39: 0.387 | X39: 0.2 | Y39: 260 | Z39: 7.1 | AA39: 0.8 | AB39: 0.209 | AC39: 11 | AD39: 0 | AF39: 0 | AG39: 0 | AH39: =AG39*3.33 -> 0 | AI39: =AG39+AM39/12+AN39/24+AO39/24 -> 12.5 | AK39: 0.26 | AL39: 1.8 | AM39: 150 | AW39: 0.018 | AX39: 0.018 | AY39: 0 | AZ39: 0.001 | BA39: 0 | BB39: 0 | BC39: 0 | BD39: 0.001 | BE39: 0 | BF39: 0 | BG39: 0.001 | BH39: 0.014 | BI39: 0.013 | BJ39: 0.001 | BK39: 0 | BL39: 0 | BM39: 0 | BO39: 0 | BQ39: 30 | BR39: 10 | BS39: 2 | BT39: 40 | BU39: 40 | BV39: 30 | BW39: 40 | BX39: 30 | BY39: 30 | BZ39: 10 | CA39: 12 | CB39: 48 | CC39: 58 | CD39: 176 | CE39: 139 | CF39: 42 | CG39: 34 | CH39: 50
A40: 33 | B40: 2009 | C40: Khoai lang nghệ | D40: TV | E40: =G40*4+H40*9+I40*4 -> 119.1 | F40: 69.9 | G40: 1.2 | H40: 0.3 | I40: =100-SUM(F40,G40,H40,K40) -> 27.9 | J40: 0.8 | K40: 0.7 | M40: 36 | N40: 56 | O40: 0.9 | P40: 30 | Q40: 0.12 | R40: 0.05 | S40: 0.6 | T40: 350 | U40: 107 | V40: 68 | AG40: 0 | AH40: =AG40*3.33 -> 0 | AI40: =AG40+AM40/12+AN40/24+AO40/24 -> 122.5 | AM40: 1470 | BO40: 0 | BQ40: 42 | BR40: 11 | BS40: 12 | BT40: 42 | BU40: 50 | BV40: 61 | BW40: 64 | BX40: 40 | BY40: 35 | BZ40: 19 | CA40: 12 | CB40: 48 | CC40: 58 | CD40: 176 | CE40: 130 | CF40: 12 | CG40: 34 | CH40: 50
A41: 34 | B41: 2010 | C41: Khoai môn | D41: TV | E41: =G41*4+H41*9+I41*4 -> 113.4 | F41: 70.8 | G41: 1.5 | H41: 0.2 | I41: =100-SUM(F41,G41,H41,K41) -> 26.4 | J41: 1.2 | K41: 1.1 | M41: 44 | N41: 44 | O41: 0.8 | P41: 4 | Q41: 0.09 | R41: 0.03 | S41: 0.1 | AG41: 0 | AH41: =AG41*3.33 -> 0 | AI41: =AG41+AM41/12+AN41/24+AO41/24 -> 0 | BO41: 0
A42: 35 | B42: 2011 | C42: Khoai nước | D42: TV | E42: =G42*4+H42*9+I42*4 -> 106.1 | F42: 72.5 | G42: 1 | H42: 0.1 | I42: =100-SUM(F42,G42,H42,K42) -> 25.3 | J42: 2 | K42: 1.1 | M42: 52 | N42: 35 | O42: 0.2 | P42: 3 | AG42: 0 | AH42: =AG42*3.33 -> 0 | AI42: =AG42+AM42/12+AN42/24+AO42/24 -> 0 | BO42: 0
...

Sheet Năng lượng_2024
B3: 1. Xác định nhu cầu dinh dưỡng cho cả ngày | M3: Bảng 1. Năng lượng chuyển hóa cơ bản
B4: Họ và tên | C4: Lê Thị A | M4: Giới tính | N4: Nam | O4: Nữ
B5: Tuổi | C5: 30 | E5: =IF(C5=0,"Nhập tuổi",_xlfn.XLOOKUP(C5,WX6:WX18,M6:M18,"Not Found",-1)) -> 30-49 tuổi | M5: Nhóm tuổi | N5: CHCB (kcal/ngày) | O5: CHCB (kcal/ngày)
B6: Giới | C6: Nữ | E6: =IF(C6=0,"Nhập giới",C6) -> Nữ | M6: 1-2 tuổi | N6: 740 | O6: 690 | WX6: 1
B7: Nghề nghiệp | C7: Cán bộ/nhân viên văn phòng (luật sư, bác sĩ, kế toán, giáo viên,..) | E7: {=IF(E6="Nam",IF(COUNTIF(N46:N63,C7),INDEX(M46:M63,MATCH(C7,N46:N63,0)),"Không tìm thấy dữ liệu"),IF(E6="Nữ",IF(COUNTIF(O46:O63,C7),INDEX(M46:M63,MATCH(C7,O46:O63,0)),"Không tìm thấy dữ liệu"),"Nhập dữ liệu giới tính tại ô C6"))} -> Lao động nhẹ | M7: 3-5 tuổi | N7: 910 | O7: 850 | WX7: 3
B8: Hệ số HĐTL | E8: {=IFERROR(INDEX(N29:P40,MATCH(E5,M29:M40,0),MATCH(E7,N41:P41,0)),0)} -> 1.5 | M8: 6-7 tuổi | N8: 1010 | O8: 940 | WX8: 6
B9: Tình trạng sức khỏe | C9: Bình thường | M9: 8-9 tuổi | N9: 1140 | O9: 1080 | WX9: 8
B10: Chiều cao (m) | C10: 1.5 | M10: 10-11 tuổi | N10: 1300 | O10: 1200 | WX10: 10
B11: Cân nặng (kg) | C11: 53 | M11: 12-14 tuổi | N11: 1470 | O11: 1360 | WX11: 12
B12: Xác định tình trạng DD (TB) | D12: BMI | E12: =IFERROR(C11/C10/C10,0) -> 23.555556 | M12: 15-17 tuổi | N12: 1610 | O12: 1360 | WX12: 15
M13: 18-29 tuổi | N13: 1470 | O13: 1170 | WX13: 18
B14: Xác định nhu cầu dinh dưỡng cho cả ngày (kcal) | M14: 30-49 tuổi | N14: 1360 | O14: 1160 | WX14: 30
E15: {=IFERROR(E8*INDEX(N6:O18,MATCH(E5,M6:M18,0),MATCH(E6,N4:O4,0))+VLOOKUP(C9,M19:O23,3,0),0)} -> 1740 | M15: 50-64 tuổi | N15: 1350 | O15: 1130 | WX15: 50
B16: Cân nặng lý tưởng | E16: =IFERROR(IF(E6="Nữ",C10*C10*21,IF(E6="Nam",C10*C10*22)),0) -> 47.25 | M16: 65-74 tuổi | N16: 1300 | O16: 1070 | WX16: 65
B17: Nhu cầu dinh dưỡng cho cả ngày cần đạt (kcal) | M17: ≥ 75 tuổi | N17: 1290 | O17: 1070 | WX17: 75
E18: =E15 -> 1740
M19: Bình thường | N19: 0 | O19: 0
M20: Phụ nữ mang thai 3 tháng đầu | N20: +50 | O20: 50
M21: Phụ nữ mang thai 3 tháng giữa | N21: +250 | O21: 250
B22: Cân đối KP | C22: %E | D22: E | E22: Kcal | G22: g | M22: Phụ nữ mang thai 3 tháng cuối | N22: +450 | O22: 450
B23: P | C23: 0.2 | D23: =$E$18 -> 1740 | E23: =C23*D23 -> 348 | F23: 4 | G23: =E23/F23 -> 87 | M23: Phụ nữ cho con bú | N23: +500 | O23: 500
B24: Pđv | E24: =E23*30% -> 104.4 | F24: 4 | G24: =G23*30% -> 26.1
B25: Ptv | E25: =E23-E24 -> 243.6 | F25: 4 | G25: =G23-G24 -> 60.9
B26: L | C26: 0.25 | D26: =$E$18 -> 1740 | E26: =C26*D26 -> 435 | F26: 9 | G26: =E26/F26 -> 48.333333
B27: Lđv | E27: =E26*50% -> 217.5 | F27: 9 | G27: =E27/F27 -> 24.166667 | M27: Bảng 2. Hệ số hoạt động thể lực so với mức NLCHCB
B28: Ltv | E28: =E26*50% -> 217.5 | F28: 9 | G28: =E28/F28 -> 24.166667 | M28: Nhóm tuổi | N28: Hoạt động thể lực nhẹ | O28: Hoạt động thể lực vừa | P28: Hoạt động thể lực nặng
B29: Car | C29: =100%-(C23+C26) -> 0.55 | D29: =$E$18 -> 1740 | E29: =C29*D29 -> 957 | F29: 4 | G29: =E29/F29 -> 239.25 | M29: 1-2 tuổi | N29: - | O29: 1.35 | P29: - | WX29: 1
M30: 3-5 tuổi | N30: - | O30: 1.45 | P30: - | WX30: 3
M31: 6-7 tuổi | N31: 1.35 | O31: 1.55 | P31: 1.75 | WX31: 6
B32: 2. Chia bữa: | M32: 8-9 tuổi | N32: 1.4 | O32: 1.6 | P32: 1.8 | WX32: 8
B33: Cả ngày | C33: % E | D33: E (kcal) | M33: 10-11 tuổi | N33: 1.45 | O33: 1.65 | P33: 1.85 | WX33: 10
C34: 100 | D34: =E18 -> 1740 | M34: 12-14 tuổi | N34: 1.5 | O34: 1.7 | P34: 1.9 | WX34: 12
B35: Sáng | C35: 0.25 | D35: =C35*$D$34 -> 435 | E35: =B35 -> Sáng | M35: 15-17 tuổi | N35: 1.55 | O35: 1.75 | P35: 1.95 | WX35: 15
E36: P | G36: =$G$23*C35 -> 21.75 | M36: 18-29 tuổi | N36: 1.5 | O36: 1.75 | P36: 2 | WX36: 18
E37: Pđv | F37: 0.3 | G37: =F37*G36 -> 6.525 | M37: 30-49 tuổi | N37: 1.5 | O37: 1.75 | P37: 2 | WX37: 30
E38: Ptv | F38: =100%-F37 -> 0.7 | G38: =F38*G36 -> 15.225 | M38: 50-64 tuổi | N38: 1.5 | O38: 1.75 | P38: 2 | WX38: 50
E39: L | G39: =$G$26*C35 -> 12.083333 | M39: 65-74 tuổi | N39: 1.45 | O39: 1.7 | P39: 1.95 | WX39: 65
E40: Lđv | F40: 0.5 | G40: =G39*F40 -> 6.0416667 | M40: ≥ 75 tuổi | N40: 1.4 | O40: 1.65 | WX40: 75
E41: Ltv | F41: =100%-F40 -> 0.5 | G41: =G39*F41 -> 6.0416667 | N41: Lao động nhẹ | O41: Lao động vừa | P41: Lao động nặng
E42: Car | G42: =$G$29*C35 -> 59.8125
...

Sheet 2.XDTD_S.Tr.T
A5: 2. Xây dựng thực đơn
D6: Hướng dẫn
E7: Nhóm bột đường | J7: Nhóm rau | R7: Nhóm quả | U7: Nhóm đạm | Y7: Nhóm chất béo | AA7: Hạt giàu béo | AC7: TP khác Sữa & sp chế biến, gia vị, đồ ăn sẵn, món ăn truyền thống
D8: NGUYÊN LIỆU | E8: TP1 | F8: TP2 | G8: TP3 | H8: TP4 | J8: TP1 | L8: TP2 | M8: TP3 | O8: TP4 | P8: TP5 | R8: TP1 | S8: TP2 | T8: TP3 | U8: TP1 | V8: TP2 | W8: TP3 | X8: TP4 | Y8: TP1 | Z8: TP2 | AA8: TP1 | AB8: TP2 | AC8: TP1 | AD8: TP2 | AE8: TP3 | DA8: CHỌN BỮA
D9: Bữa sáng | E9: Gạo lứt | F9: Bánh quẩy nóng | J9: Cải xanh | L9: Thìa là | M9: Giá đậu xanh | U9: Cá chép | Y9: Mỡ lợn nước | AA9: Sữa đậu nành (100g đậu/lít) | DA9: SÁNG
D10: Chọn TV/ĐV | E10: TV | F10: TV | J10: TV | L10: TV | M10: TV | U10: ĐV | Y10: TV | AA10: TV | DA10: SÁNG
D11: Định lượng (g/ml) | E11: 180 | F11: 15 | J11: 40 | L11: 10 | M11: 25 | U11: 55 | Y11: 5.5 | AA11: 200 | DA11: SÁNG
E12: =IF(E9=0,0,100*$R$44/_xlfn.XLOOKUP(E9,'FCDB 2017 (full)'!$C:$C,'FCDB 2017 (full)'!$I:$I)) -> #NAME? | F12: =IF(F9=0,0,100*$R$44/_xlfn.XLOOKUP(F9,'FCDB 2017 (full)'!$C:$C,'FCDB 2017 (full)'!$I:$I)) -> #NAME? | G12: =IF(G9=0,0,100*$R$44/_xlfn.XLOOKUP(G9,'FCDB 2017 (full)'!$C:$C,'FCDB 2017 (full)'!$I:$I)) -> 0 | H12: =IF(H9=0,0,100*$R$44/_xlfn.XLOOKUP(H9,'FCDB 2017 (full)'!$C:$C,'FCDB 2017 (full)'!$I:$I)) -> 0 | J12: =IF(J9=0,0,100*$R$44/_xlfn.XLOOKUP(J9,'FCDB 2017 (full)'!$C:$C,'FCDB 2017 (full)'!$I:$I)) -> #NAME? | L12: =IF(L9=0,0,100*$R$44/_xlfn.XLOOKUP(L9,'FCDB 2017 (full)'!$C:$C,'FCDB 2017 (full)'!$I:$I)) -> #NAME? | M12: =IF(M9=0,0,100*$R$44/_xlfn.XLOOKUP(M9,'FCDB 2017 (full)'!$C:$C,'FCDB 2017 (full)'!$I:$I)) -> #NAME? | R12: =IF(R9=0,0,100*$R$44/_xlfn.XLOOKUP(R9,'FCDB 2017 (full)'!$C:$C,'FCDB 2017 (full)'!$I:$I)) -> 0 | S12: =IF(S9=0,0,100*$R$44/_xlfn.XLOOKUP(S9,'FCDB 2017 (full)'!$C:$C,'FCDB 2017 (full)'!$I:$I)) -> 0 | T12: =IF(T9=0,0,100*$R$44/_xlfn.XLOOKUP(T9,'FCDB 2017 (full)'!$C:$C,'FCDB 2017 (full)'!$I:$I)) -> 0 | DA12: SÁNG
DA13: SÁNG
F14: =D9 -> Bữa sáng | H14: Khối lượng | I14: Năng lượng/100g | J14: Năng lượng | K14: P/100g | L14: Protein | N14: L/100g | O14: Lipid | Q14: C/100g | R14: Carbohydrate | S14: Chất xơ (crude fiber) | T14: Tro (ash) | U14: Đường tổng (total sugar) | V14: Calcium (Ca) | W14: Photphorous (P) | X14: Iron (Fe) | Y14: Vitamin C | Z14: Vitamin B1 | AA14: Vitamin B2 | AB14: Vitamin PP | AC14: Sodium (Na) | AD14: Potassium (K) | AE14: Magnesium (Mg) | AF14: Manganese (Mn) | AG14: Zinc (Zn) | AH14: Copper (Cu) | AI14: Selenium (Se) | AJ14: Acid pantothenic | AK14: Vitamin B6 | AL14: Folate tổng số | AM14: Acid folic (vitamin B9) | AN14: Biotin (vitamin H) | AO14: Vitamin B12 | AP14: Vitamin A (retinol) | AQ14: Retinol | AR14: Vitamin A (RAE) | AS14: Vitamin D | AT14: Vitamin E | AU14: Vitamin K | AV14: Betacarotene | AW14: Alphacarotene | AX14: Betacryptoxanthin | AY14: Lycopene | AZ14: Lutein + zeaxanthin | BA14: Isoflavone tổng số | BB14: Daidzein | BC14: Genistein | BD14: Glycetin | BE14: Purine | BF14: TS Axit béo no | BG14: Palmitic (C16:0) | BH14: Margaric (C17:0) | BI14: Stearic (C18:0) | BJ14: Arachidic (C20:0) | BK14: Behenic (C22:0) | BL14: Lignoceric (C24:0) | BM14: TS acid béo không no 1 nối đôi | BN14: Myristoleic (C14:1) | BO14: Palmitoleic (C16:1) | BP14: Oleic (C18:1) | BQ14: TS acid béo không no nhiều nối đôi | BR14: Linoleic | BS14: Linolenic | BT14: Arachidonic (C20:4) | BU14: EPA (C20:5 n3) | BV14: DHA (C22:6 n3) | BW14: TS acid béo trans | BX14: Cholesterol | BY14: Phytosterol | BZ14: Lysin | CA14: Methionin | CB14: Tryptophan | CC14: Phenylalanin | CD14: Threonin | CE14: Valine | CF14: Leucine | CG14: Isoleucine | CH14: Arginine | CI14: Histidine | CJ14: Cystine | CK14: Tyrosine | CL14: Alanine | CM14: Aspartic acid | CN14: Glutamic acid | CO14: Glycine | CP14: Proline | CQ14: Serine | DA14: SÁNG
F15: Nguyên liệu | G15: TV/ ĐV | L15: ĐV | M15: TV | O15: ĐV | P15: TV | DA15: SÁNG
F16: =IFERROR(VLOOKUP($D$9,$D:$AE,2,0),0) -> Gạo lứt | G16: =IF(F16=0,0,IF(_xlfn.XLOOKUP(F16,$E$9:$AE$9,$E$10:$AE$10)=0,"Nhập ĐV/TV",_xlfn.XLOOKUP(F16,$E$9:$AE$9,$E$10:$AE$10))) -> #NAME? | H16: =IFERROR(INDEX($E$11:$AE$11,MATCH(F16,$E$9:$AE$9,0)),0) -> 180 | I16: =IFERROR(_xlfn.XLOOKUP($F16,'FCDB 2017 (full)'!$C:$C,'FCDB 2017 (full)'!$E:$E),0) -> 0 | J16: =$H16*I16/100 -> 0 | K16: =IFERROR(_xlfn.XLOOKUP($F16,'FCDB 2017 (full)'!$C:$C,'FCDB 2017 (full)'!$G:$G),0) -> 0 | L16: =IF($G16=L$15,$H16*$K16/100,0) -> #NAME? | M16: =IF($G16=M$15,$H16*$K16/100,0) -> #NAME? | N16: =IFERROR(_xlfn.XLOOKUP($F16,'FCDB 2017 (full)'!$C:$C,'FCDB 2017 (full)'!$H:$H),0) -> 0 | O16: =IF($G16=O$15,$H16*$N16/100,0) -> #NAME? | P16: =IF($G16=P$15,$H16*$N16/100,0) -> #NAME? | Q16: =IFERROR(_xlfn.XLOOKUP($F16,'FCDB 2017 (full)'!$C:$C,'FCDB 2017 (full)'!$I:$I),0) -> 0 | R16: =$H16*Q16/100 -> 0 | S16: =IFERROR(_xlfn.XLOOKUP($F16,'FCDB 2017 (full)'!$C:$C,'FCDB 2017 (full)'!$J:$J)*$H16/100,0) -> 0 | T16: =IFERROR(_xlfn.XLOOKUP($F16,'FCDB 2017 (full)'!$C:$C,'FCDB 2017 (full)'!$K:$K)*$H16/100,0) -> 0 | U16: =IFERROR(_xlfn.XLOOKUP($F16,'FCDB 2017 (full)'!$C:$C,'FCDB 2017 (full)'!$L:$L)*$H16/100,0) -> 0 | V16: =IFERROR(_xlfn.XLOOKUP($F16,'FCDB 2017 (full)'!$C:$C,'FCDB 2017 (full)'!$M:$M)*$H16/100,0) -> 0 | W16: =IFERROR(_xlfn.XLOOKUP($F16,'FCDB 2017 (full)'!$C:$C,'FCDB 2017 (full)'!$N:$N)*$H16/100,0) -> 0 | X16: =IFERROR(_xlfn.XLOOKUP($F16,'FCDB 2017 (full)'!$C:$C,'FCDB 2017 (full)'!$O:$O)*$H16/100,0) -> 0 | Y16: =IFERROR(_xlfn.XLOOKUP($F16,'FCDB 2017 (full)'!$C:$C,'FCDB 2017 (full)'!$P:$P)*$H16/100,0) -> 0 | Z16: =IFERROR(_xlfn.XLOOKUP($F16,'FCDB 2017 (full)'!$C:$C,'FCDB 2017 (full)'!$Q:$Q)*$H16/100,0) -> 0 | AA16: =IFERROR(_xlfn.XLOOKUP($F16,'FCDB 2017 (full)'!$C:$C,'FCDB 2017 (full)'!$R:$R)*$H16/100,0) -> 0 | AB16: =IFERROR(_xlfn.XLOOKUP($F16,'FCDB 2017 (full)'!$C:$C,'FCDB 2017 (full)'!$S:$S)*$H16/100,0) -> 0 | AC16: =IFERROR(_xlfn.XLOOKUP($F16,'FCDB 2017 (full)'!$C:$C,'FCDB 2017 (full)'!$T:$T)*$H16/100,0) -> 0 | AD16: =IFERROR(_xlfn.XLOOKUP($F16,'FCDB 2017 (full)'!$C:$C,'FCDB 2017 (full)'!$U:$U)*$H16/100,0) -> 0 | AE16: =IFERROR(_xlfn.XLOOKUP($F16,'FCDB 2017 (full)'!$C:$C,'FCDB 2017 (full)'!$V:$V)*$H16/100,0) -> 0 | AF16: =IFERROR(_xlfn.XLOOKUP($F16,'FCDB 2017 (full)'!$C:$C,'FCDB 2017 (full)'!$W:$W)*$H16/100,0) -> 0 | AG16: =IFERROR(_xlfn.XLOOKUP($F16,'FCDB 2017 (full)'!$C:$C,'FCDB 2017 (full)'!$X:$X)*$H16/100,0) -> 0 | AH16: =IFERROR(_xlfn.XLOOKUP($F16,'FCDB 2017 (full)'!$C:$C,'FCDB 2017 (full)'!$Y:$Y)*$H16/100,0) -> 0 | AI16: =IFERROR(_xlfn.XLOOKUP($F16,'FCDB 2017 (full)'!$C:$C,'FCDB 2017 (full)'!$Z:$Z)*$H16/100,0) -> 0 | AJ16: =IFERROR(_xlfn.XLOOKUP($F16,'FCDB 2017 (full)'!$C:$C,'FCDB 2017 (full)'!$AA:$AA)*$H16/100,0) -> 0 | AK16: =IFERROR(_xlfn.XLOOKUP($F16,'FCDB 2017 (full)'!$C:$C,'FCDB 2017 (full)'!$AB:$AB)*$H16/100,0) -> 0 | AL16: =IFERROR(_xlfn.XLOOKUP($F16,'FCDB 2017 (full)'!$C:$C,'FCDB 2017 (full)'!$AC:$AC)*$H16/100,0) -> 0 | AM16: =IFERROR(_xlfn.XLOOKUP($F16,'FCDB 2017 (full)'!$C:$C,'FCDB 2017 (full)'!$AD:$AD)*$H16/100,0) -> 0 | AN16: =IFERROR(_xlfn.XLOOKUP($F16,'FCDB 2017 (full)'!$C:$C,'FCDB 2017 (full)'!$AE:$AE)*$H16/100,0) -> 0 | AO16: =IFERROR(_xlfn.XLOOKUP($F16,'FCDB 2017 (full)'!$C:$C,'FCDB 2017 (full)'!$AF:$AF)*$H16/100,0) -> 0 | AP16: =IFERROR(_xlfn.XLOOKUP($F16,'FCDB 2017 (full)'!$C:$C,'FCDB 2017 (full)'!$AG:$AG)*$H16/100,0) -> 0 | AQ16: =IFERROR(_xlfn.XLOOKUP($F16,'FCDB 2017 (full)'!$C:$C,'FCDB 2017 (full)'!$AH:$AH)*$H16/100,0) -> 0 | AR16: =IFERROR(_xlfn.XLOOKUP($F16,'FCDB 2017 (full)'!$C:$C,'FCDB 2017 (full)'!$AI:$AI)*$H16/100,0) -> 0 | AS16: =IFERROR(_xlfn.XLOOKUP($F16,'FCDB 2017 (full)'!$C:$C,'FCDB 2017 (full)'!$AJ:$AJ)*$H16/100,0) -> 0 | AT16: =IFERROR(_xlfn.XLOOKUP($F16,'FCDB 2017 (full)'!$C:$C,'FCDB 2017 (full)'!$AK:$AK)*$H16/100,0) -> 0 | AU16: =IFERROR(_xlfn.XLOOKUP($F16,'FCDB 2017 (full)'!$C:$C,'FCDB 2017 (full)'!$AK:$AK)*$H16/100,0) -> 0 | AV16: =IFERROR(_xlfn.XLOOKUP($F16,'FCDB 2017 (full)'!$C:$C,'FCDB 2017 (full)'!$AM:$AM)*$H16/100,0) -> 0 | AW16: =IFERROR(_xlfn.XLOOKUP($F16,'FCDB 2017 (full)'!$C:$C,'FCDB 2017 (full)'!$AN:$AN)*$H16/100,0) -> 0 | AX16: =IFERROR(_xlfn.XLOOKUP($F16,'FCDB 2017 (full)'!$C:$C,'FCDB 2017 (full)'!$AO:$AO)*$H16/100,0) -> 0 | AY16: =IFERROR(_xlfn.XLOOKUP($F16,'FCDB 2017 (full)'!$C:$C,'FCDB 2017 (full)'!$AP:$AP)*$H16/100,0) -> 0 | AZ16: =IFERROR(_xlfn.XLOOKUP($F16,'FCDB 2017 (full)'!$C:$C,'FCDB 2017 (full)'!$AQ:$AQ)*$H16/100,0) -> 0 | BA16: =IFERROR(_xlfn.XLOOKUP($F16,'FCDB 2017 (full)'!$C:$C,'FCDB 2017 (full)'!$AR:$AR)*$H16/100,0) -> 0 | BB16: =IFERROR(_xlfn.XLOOKUP($F16,'FCDB 2017 (full)'!$C:$C,'FCDB 2017 (full)'!$AS:$AS)*$H16/100,0) -> 0 | BC16: =IFERROR(_xlfn.XLOOKUP($F16,'FCDB 2017 (full)'!$C:$C,'FCDB 2017 (full)'!$AT:$AT)*$H16/100,0) -> 0 | BD16: =IFERROR(_xlfn.XLOOKUP($F16,'FCDB 2017 (full)'!$C:$C,'FCDB 2017 (full)'!$AU:$AU)*$H16/100,0) -> 0 | BE16: =IFERROR(_xlfn.XLOOKUP($F16,'FCDB 2017 (full)'!$C:$C,'FCDB 2017 (full)'!$AV:$AV)*$H16/100,0) -> 0 | BF16: =IFERROR(_xlfn.XLOOKUP($F16,'FCDB 2017 (full)'!$C:$C,'FCDB 2017 (full)'!$AW:$AW)*$H16/100,0) -> 0 | BG16: =IFERROR(_xlfn.XLOOKUP($F16,'FCDB 2017 (full)'!$C:$C,'FCDB 2017 (full)'!$AX:$AX)*$H16/100,0) -> 0 | BH16: =IFERROR(_xlfn.XLOOKUP($F16,'FCDB 2017 (full)'!$C:$C,'FCDB 2017 (full)'!$AY:$AY)*$H16/100,0) -> 0 | BI16: =IFERROR(_xlfn.XLOOKUP($F16,'FCDB 2017 (full)'!$C:$C,'FCDB 2017 (full)'!$AZ:$AZ)*$H16/100,0) -> 0 | BJ16: =IFERROR(_xlfn.XLOOKUP($F16,'FCDB 2017 (full)'!$C:$C,'FCDB 2017 (full)'!$BA:$BA)*$H16/100,0) -> 0 | BK16: =IFERROR(_xlfn.XLOOKUP($F16,'FCDB 2017 (full)'!$C:$C,'FCDB 2017 (full)'!$BB:$BB)*$H16/100,0) -> 0 | BL16: =IFERROR(_xlfn.XLOOKUP($F16,'FCDB 2017 (full)'!$C:$C,'FCDB 2017 (full)'!$BC:$BC)*$H16/100,0) -> 0 | BM16: =IFERROR(_xlfn.XLOOKUP($F16,'FCDB 2017 (full)'!$C:$C,'FCDB 2017 (full)'!$BD:$BD)*$H16/100,0) -> 0 | BN16: =IFERROR(_xlfn.XLOOKUP($F16,'FCDB 2017 (full)'!$C:$C,'FCDB 2017 (full)'!$BE:$BE)*$H16/100,0) -> 0 | BO16: =IFERROR(_xlfn.XLOOKUP($F16,'FCDB 2017 (full)'!$C:$C,'FCDB 2017 (full)'!$BF:$BF)*$H16/100,0) -> 0 | BP16: =IFERROR(_xlfn.XLOOKUP($F16,'FCDB 2017 (full)'!$C:$C,'FCDB 2017 (full)'!$BG:$BG)*$H16/100,0) -> 0 | BQ16: =IFERROR(_xlfn.XLOOKUP($F16,'FCDB 2017 (full)'!$C:$C,'FCDB 2017 (full)'!$BH:$BH)*$H16/100,0) -> 0 | BR16: =IFERROR(_xlfn.XLOOKUP($F16,'FCDB 2017 (full)'!$C:$C,'FCDB 2017 (full)'!$BI:$BI)*$H16/100,0) -> 0 | BS16: =IFERROR(_xlfn.XLOOKUP($F16,'FCDB 2017 (full)'!$C:$C,'FCDB 2017 (full)'!$BJ:$BJ)*$H16/100,0) -> 0 | BT16: =IFERROR(_xlfn.XLOOKUP($F16,'FCDB 2017 (full)'!$C:$C,'FCDB 2017 (full)'!$BK:$BK)*$H16/100,0) -> 0 | BU16: =IFERROR(_xlfn.XLOOKUP($F16,'FCDB 2017 (full)'!$C:$C,'FCDB 2017 (full)'!$BL:$BL)*$H16/100,0) -> 0 | BV16: =IFERROR(_xlfn.XLOOKUP($F16,'FCDB 2017 (full)'!$C:$C,'FCDB 2017 (full)'!$BM:$BM)*$H16/100,0) -> 0 | BW16: =IFERROR(_xlfn.XLOOKUP($F16,'FCDB 2017 (full)'!$C:$C,'FCDB 2017 (full)'!$BN:$BN)*$H16/100,0) -> 0 | BX16: =IFERROR(_xlfn.XLOOKUP($F16,'FCDB 2017 (full)'!$C:$C,'FCDB 2017 (full)'!$BO:$BO)*$H16/100,0) -> 0 | BY16: =IFERROR(_xlfn.XLOOKUP($F16,'FCDB 2017 (full)'!$C:$C,'FCDB 2017 (full)'!$BP:$BP)*$H16/100,0) -> 0 | BZ16: =IFERROR(_xlfn.XLOOKUP($F16,'FCDB 2017 (full)'!$C:$C,'FCDB 2017 (full)'!$BQ:$BQ)*$H16/100,0) -> 0 | CA16: =IFERROR(_xlfn.XLOOKUP($F16,'FCDB 2017 (full)'!$C:$C,'FCDB 2017 (full)'!$BR:$BR)*$H16/100,0) -> 0 | CB16: =IFERROR(_xlfn.XLOOKUP($F16,'FCDB 2017 (full)'!$C:$C,'FCDB 2017 (full)'!$BS:$BS)*$H16/100,0) -> 0 | CC16: =IFERROR(_xlfn.XLOOKUP($F16,'FCDB 2017 (full)'!$C:$C,'FCDB 2017 (full)'!$BT:$BT)*$H16/100,0) -> 0 | CD16: =IFERROR(_xlfn.XLOOKUP($F16,'FCDB 2017 (full)'!$C:$C,'FCDB 2017 (full)'!$BU:$BU)*$H16/100,0) -> 0 | CE16: =IFERROR(_xlfn.XLOOKUP($F16,'FCDB 2017 (full)'!$C:$C,'FCDB 2017 (full)'!$BV:$BV)*$H16/100,0) -> 0 | CF16: =IFERROR(_xlfn.XLOOKUP($F16,'FCDB 2017 (full)'!$C:$C,'FCDB 2017 (full)'!$BW:$BW)*$H16/100,0) -> 0 | CG16: =IFERROR(_xlfn.XLOOKUP($F16,'FCDB 2017 (full)'!$C:$C,'FCDB 2017 (full)'!$BX:$BX)*$H16/100,0) -> 0 | CH16: =IFERROR(_xlfn.XLOOKUP($F16,'FCDB 2017 (full)'!$C:$C,'FCDB 2017 (full)'!$BY:$BY)*$H16/100,0) -> 0 | CI16: =IFERROR(_xlfn.XLOOKUP($F16,'FCDB 2017 (full)'!$C:$C,'FCDB 2017 (full)'!$BZ:$BZ)*$H16/100,0) -> 0 | CJ16: =IFERROR(_xlfn.XLOOKUP($F16,'FCDB 2017 (full)'!$C:$C,'FCDB 2017 (full)'!$CA:$CA)*$H16/100,0) -> 0 | CK16: =IFERROR(_xlfn.XLOOKUP($F16,'FCDB 2017 (full)'!$C:$C,'FCDB 2017 (full)'!$CB:$CB)*$H16/100,0) -> 0 | CL16: =IFERROR(_xlfn.XLOOKUP($F16,'FCDB 2017 (full)'!$C:$C,'FCDB 2017 (full)'!$CC:$CC)*$H16/100,0) -> 0 | CM16: =IFERROR(_xlfn.XLOOKUP($F16,'FCDB 2017 (full)'!$C:$C,'FCDB 2017 (full)'!$CD:$CD)*$H16/100,0) -> 0 | CN16: =IFERROR(_xlfn.XLOOKUP($F16,'FCDB 2017 (full)'!$C:$C,'FCDB 2017 (full)'!$CE:$CE)*$H16/100,0) -> 0 | CO16: =IFERROR(_xlfn.XLOOKUP($F16,'FCDB 2017 (full)'!$C:$C,'FCDB 2017 (full)'!$CF:$CF)*$H16/100,0) -> 0 | CP16: =IFERROR(_xlfn.XLOOKUP($F16,'FCDB 2017 (full)'!$C:$C,'FCDB 2017 (full)'!$CG:$CG)*$H16/100,0) -> 0 | CQ16: =IFERROR(_xlfn.XLOOKUP($F16,'FCDB 2017 (full)'!$C:$C,'FCDB 2017 (full)'!$CH:$CH)*$H16/100,0) -> 0 | DA16: SÁNG
F17: =IFERROR(VLOOKUP($D$9,$D:$AE,3,0),0) -> Bánh quẩy nóng | G17: {=IF(F17=0,0,IF(_xlfn.XLOOKUP(F17,$E$9:$AE$9,$E$10:$AE$10)=0,"Nhập ĐV/TV",_xlfn.XLOOKUP(F17,$E$9:$AE$9,$E$10:$AE$10)))} -> #NAME? | H17: {=IFERROR(INDEX($E$11:$AE$11,MATCH(F17,$E$9:$AE$9,0)),0)} -> 15 | I17: =IFERROR(_xlfn.XLOOKUP($F17,'FCDB 2017 (full)'!$C:$C,'FCDB 2017 (full)'!$E:$E),0) -> 0 | J17: =$H17*I17/100 -> 0 | K17: =IFERROR(_xlfn.XLOOKUP($F17,'FCDB 2017 (full)'!$C:$C,'FCDB 2017 (full)'!$G:$G),0) -> 0 | L17: =IF($G17=L$15,$H17*$K17/100,0) -> #NAME? | M17: =IF($G17=M$15,$H17*$K17/100,0) -> #NAME? | N17: =IFERROR(_xlfn.XLOOKUP($F17,'FCDB 2017 (full)'!$C:$C,'FCDB 2017 (full)'!$H:$H),0) -> 0 | O17: =IF($G17=O$15,$H17*$N17/100,0) -> #NAME? | P17: =IF($G17=P$15,$H17*$N17/100,0) -> #NAME? | Q17: =IFERROR(_xlfn.XLOOKUP($F17,'FCDB 2017 (full)'!$C:$C,'FCDB 2017 (full)'!$I:$I),0) -> 0 | R17: =$H17*Q17/100 -> 0 | S17: =IFERROR(_xlfn.XLOOKUP($F17,'FCDB 2017 (full)'!$C:$C,'FCDB 2017 (full)'!$J:$J)*$H17/100,0) -> 0 | T17: =IFERROR(_xlfn.XLOOKUP($F17,'FCDB 2017 (full)'!$C:$C,'FCDB 2017 (full)'!$K:$K)*$H17/100,0) -> 0 | U17: =IFERROR(_xlfn.XLOOKUP($F17,'FCDB 2017 (full)'!$C:$C,'FCDB 2017 (full)'!$L:$L)*$H17/100,0) -> 0 | V17: =IFERROR(_xlfn.XLOOKUP($F17,'FCDB 2017 (full)'!$C:$C,'FCDB 2017 (full)'!$M:$M)*$H17/100,0) -> 0 | W17: =IFERROR(_xlfn.XLOOKUP($F17,'FCDB 2017 (full)'!$C:$C,'FCDB 2017 (full)'!$N:$N)*$H17/100,0) -> 0 | X17: =IFERROR(_xlfn.XLOOKUP($F17,'FCDB 2017 (full)'!$C:$C,'FCDB 2017 (full)'!$O:$O)*$H17/100,0) -> 0 | Y17: =IFERROR(_xlfn.XLOOKUP($F17,'FCDB 2017 (full)'!$C:$C,'FCDB 2017 (full)'!$P:$P)*$H17/100,0) -> 0 | Z17: =IFERROR(_xlfn.XLOOKUP($F17,'FCDB 2017 (full)'!$C:$C,'FCDB 2017 (full)'!$Q:$Q)*$H17/100,0) -> 0 | AA17: =IFERROR(_xlfn.XLOOKUP($F17,'FCDB 2017 (full)'!$C:$C,'FCDB 2017 (full)'!$R:$R)*$H17/100,0) -> 0 | AB17: =IFERROR(_xlfn.XLOOKUP($F17,'FCDB 2017 (full)'!$C:$C,'FCDB 2017 (full)'!$S:$S)*$H17/100,0) -> 0 | AC17: =IFERROR(_xlfn.XLOOKUP($F17,'FCDB 2017 (full)'!$C:$C,'FCDB 2017 (full)'!$T:$T)*$H17/100,0) -> 0 | AD17: =IFERROR(_xlfn.XLOOKUP($F17,'FCDB 2017 (full)'!$C:$C,'FCDB 2017 (full)'!$U:$U)*$H17/100,0) -> 0 | AE17: =IFERROR(_xlfn.XLOOKUP($F17,'FCDB 2017 (full)'!$C:$C,'FCDB 2017 (full)'!$V:$V)*$H17/100,0) -> 0 | AF17: =IFERROR(_xlfn.XLOOKUP($F17,'FCDB 2017 (full)'!$C:$C,'FCDB 2017 (full)'!$W:$W)*$H17/100,0) -> 0 | AG17: =IFERROR(_xlfn.XLOOKUP($F17,'FCDB 2017 (full)'!$C:$C,'FCDB 2017 (full)'!$X:$X)*$H17/100,0) -> 0 | AH17: =IFERROR(_xlfn.XLOOKUP($F17,'FCDB 2017 (full)'!$C:$C,'FCDB 2017 (full)'!$Y:$Y)*$H17/100,0) -> 0 | AI17: =IFERROR(_xlfn.XLOOKUP($F17,'FCDB 2017 (full)'!$C:$C,'FCDB 2017 (full)'!$Z:$Z)*$H17/100,0) -> 0 | AJ17: =IFERROR(_xlfn.XLOOKUP($F17,'FCDB 2017 (full)'!$C:$C,'FCDB 2017 (full)'!$AA:$AA)*$H17/100,0) -> 0 | AK17: =IFERROR(_xlfn.XLOOKUP($F17,'FCDB 2017 (full)'!$C:$C,'FCDB 2017 (full)'!$AB:$AB)*$H17/100,0) -> 0 | AL17: =IFERROR(_xlfn.XLOOKUP($F17,'FCDB 2017 (full)'!$C:$C,'FCDB 2017 (full)'!$AC:$AC)*$H17/100,0) -> 0 | AM17: =IFERROR(_xlfn.XLOOKUP($F17,'FCDB 2017 (full)'!$C:$C,'FCDB 2017 (full)'!$AD:$AD)*$H17/100,0) -> 0 | AN17: =IFERROR(_xlfn.XLOOKUP($F17,'FCDB 2017 (full)'!$C:$C,'FCDB 2017 (full)'!$AE:$AE)*$H17/100,0) -> 0 | AO17: =IFERROR(_xlfn.XLOOKUP($F17,'FCDB 2017 (full)'!$C:$C,'FCDB 2017 (full)'!$AF:$AF)*$H17/100,0) -> 0 | AP17: =IFERROR(_xlfn.XLOOKUP($F17,'FCDB 2017 (full)'!$C:$C,'FCDB 2017 (full)'!$AG:$AG)*$H17/100,0) -> 0 | AQ17: =IFERROR(_xlfn.XLOOKUP($F17,'FCDB 2017 (full)'!$C:$C,'FCDB 2017 (full)'!$AH:$AH)*$H17/100,0) -> 0 | AR17: =IFERROR(_xlfn.XLOOKUP($F17,'FCDB 2017 (full)'!$C:$C,'FCDB 2017 (full)'!$AI:$AI)*$H17/100,0) -> 0 | AS17: =IFERROR(_xlfn.XLOOKUP($F17,'FCDB 2017 (full)'!$C:$C,'FCDB 2017 (full)'!$AJ:$AJ)*$H17/100,0) -> 0 | AT17: =IFERROR(_xlfn.XLOOKUP($F17,'FCDB 2017 (full)'!$C:$C,'FCDB 2017 (full)'!$AK:$AK)*$H17/100,0) -> 0 | AU17: =IFERROR(_xlfn.XLOOKUP($F17,'FCDB 2017 (full)'!$C:$C,'FCDB 2017 (full)'!$AK:$AK)*$H17/100,0) -> 0 | AV17: =IFERROR(_xlfn.XLOOKUP($F17,'FCDB 2017 (full)'!$C:$C,'FCDB 2017 (full)'!$AM:$AM)*$H17/100,0) -> 0 | AW17: =IFERROR(_xlfn.XLOOKUP($F17,'FCDB 2017 (full)'!$C:$C,'FCDB 2017 (full)'!$AN:$AN)*$H17/100,0) -> 0 | AX17: =IFERROR(_xlfn.XLOOKUP($F17,'FCDB 2017 (full)'!$C:$C,'FCDB 2017 (full)'!$AO:$AO)*$H17/100,0) -> 0 | AY17: =IFERROR(_xlfn.XLOOKUP($F17,'FCDB 2017 (full)'!$C:$C,'FCDB 2017 (full)'!$AP:$AP)*$H17/100,0) -> 0 | AZ17: =IFERROR(_xlfn.XLOOKUP($F17,'FCDB 2017 (full)'!$C:$C,'FCDB 2017 (full)'!$AQ:$AQ)*$H17/100,0) -> 0 | BA17: =IFERROR(_xlfn.XLOOKUP($F17,'FCDB 2017 (full)'!$C:$C,'FCDB 2017 (full)'!$AR:$AR)*$H17/100,0) -> 0 | BB17: =IFERROR(_xlfn.XLOOKUP($F17,'FCDB 2017 (full)'!$C:$C,'FCDB 2017 (full)'!$AS:$AS)*$H17/100,0) -> 0 | BC17: =IFERROR(_xlfn.XLOOKUP($F17,'FCDB 2017 (full)'!$C:$C,'FCDB 2017 (full)'!$AT:$AT)*$H17/100,0) -> 0 | BD17: =IFERROR(_xlfn.XLOOKUP($F17,'FCDB 2017 (full)'!$C:$C,'FCDB 2017 (full)'!$AU:$AU)*$H17/100,0) -> 0 | BE17: =IFERROR(_xlfn.XLOOKUP($F17,'FCDB 2017 (full)'!$C:$C,'FCDB 2017 (full)'!$AV:$AV)*$H17/100,0) -> 0 | BF17: =IFERROR(_xlfn.XLOOKUP($F17,'FCDB 2017 (full)'!$C:$C,'FCDB 2017 (full)'!$AW:$AW)*$H17/100,0) -> 0 | BG17: =IFERROR(_xlfn.XLOOKUP($F17,'FCDB 2017 (full)'!$C:$C,'FCDB 2017 (full)'!$AX:$AX)*$H17/100,0) -> 0 | BH17: =IFERROR(_xlfn.XLOOKUP($F17,'FCDB 2017 (full)'!$C:$C,'FCDB 2017 (full)'!$AY:$AY)*$H17/100,0) -> 0 | BI17: =IFERROR(_xlfn.XLOOKUP($F17,'FCDB 2017 (full)'!$C:$C,'FCDB 2017 (full)'!$AZ:$AZ)*$H17/100,0) -> 0 | BJ17: =IFERROR(_xlfn.XLOOKUP($F17,'FCDB 2017 (full)'!$C:$C,'FCDB 2017 (full)'!$BA:$BA)*$H17/100,0) -> 0 | BK17: =IFERROR(_xlfn.XLOOKUP($F17,'FCDB 2017 (full)'!$C:$C,'FCDB 2017 (full)'!$BB:$BB)*$H17/100,0) -> 0 | BL17: =IFERROR(_xlfn.XLOOKUP($F17,'FCDB 2017 (full)'!$C:$C,'FCDB 2017 (full)'!$BC:$BC)*$H17/100,0) -> 0 | BM17: =IFERROR(_xlfn.XLOOKUP($F17,'FCDB 2017 (full)'!$C:$C,'FCDB 2017 (full)'!$BD:$BD)*$H17/100,0) -> 0 | BN17: =IFERROR(_xlfn.XLOOKUP($F17,'FCDB 2017 (full)'!$C:$C,'FCDB 2017 (full)'!$BE:$BE)*$H17/100,0) -> 0 | BO17: =IFERROR(_xlfn.XLOOKUP($F17,'FCDB 2017 (full)'!$C:$C,'FCDB 2017 (full)'!$BF:$BF)*$H17/100,0) -> 0 | BP17: =IFERROR(_xlfn.XLOOKUP($F17,'FCDB 2017 (full)'!$C:$C,'FCDB 2017 (full)'!$BG:$BG)*$H17/100,0) -> 0 | BQ17: =IFERROR(_xlfn.XLOOKUP($F17,'FCDB 2017 (full)'!$C:$C,'FCDB 2017 (full)'!$BH:$BH)*$H17/100,0) -> 0 | BR17: =IFERROR(_xlfn.XLOOKUP($F17,'FCDB 2017 (full)'!$C:$C,'FCDB 2017 (full)'!$BI:$BI)*$H17/100,0) -> 0 | BS17: =IFERROR(_xlfn.XLOOKUP($F17,'FCDB 2017 (full)'!$C:$C,'FCDB 2017 (full)'!$BJ:$BJ)*$H17/100,0) -> 0 | BT17: =IFERROR(_xlfn.XLOOKUP($F17,'FCDB 2017 (full)'!$C:$C,'FCDB 2017 (full)'!$BK:$BK)*$H17/100,0) -> 0 | BU17: =IFERROR(_xlfn.XLOOKUP($F17,'FCDB 2017 (full)'!$C:$C,'FCDB 2017 (full)'!$BL:$BL)*$H17/100,0) -> 0 | BV17: =IFERROR(_xlfn.XLOOKUP($F17,'FCDB 2017 (full)'!$C:$C,'FCDB 2017 (full)'!$BM:$BM)*$H17/100,0) -> 0 | BW17: =IFERROR(_xlfn.XLOOKUP($F17,'FCDB 2017 (full)'!$C:$C,'FCDB 2017 (full)'!$BN:$BN)*$H17/100,0) -> 0 | BX17: =IFERROR(_xlfn.XLOOKUP($F17,'FCDB 2017 (full)'!$C:$C,'FCDB 2017 (full)'!$BO:$BO)*$H17/100,0) -> 0 | BY17: =IFERROR(_xlfn.XLOOKUP($F17,'FCDB 2017 (full)'!$C:$C,'FCDB 2017 (full)'!$BP:$BP)*$H17/100,0) -> 0 | BZ17: =IFERROR(_xlfn.XLOOKUP($F17,'FCDB 2017 (full)'!$C:$C,'FCDB 2017 (full)'!$BQ:$BQ)*$H17/100,0) -> 0 | CA17: =IFERROR(_xlfn.XLOOKUP($F17,'FCDB 2017 (full)'!$C:$C,'FCDB 2017 (full)'!$BR:$BR)*$H17/100,0) -> 0 | CB17: =IFERROR(_xlfn.XLOOKUP($F17,'FCDB 2017 (full)'!$C:$C,'FCDB 2017 (full)'!$BS:$BS)*$H17/100,0) -> 0 | CC17: =IFERROR(_xlfn.XLOOKUP($F17,'FCDB 2017 (full)'!$C:$C,'FCDB 2017 (full)'!$BT:$BT)*$H17/100,0) -> 0 | CD17: =IFERROR(_xlfn.XLOOKUP($F17,'FCDB 2017 (full)'!$C:$C,'FCDB 2017 (full)'!$BU:$BU)*$H17/100,0) -> 0 | CE17: =IFERROR(_xlfn.XLOOKUP($F17,'FCDB 2017 (full)'!$C:$C,'FCDB 2017 (full)'!$BV:$BV)*$H17/100,0) -> 0 | CF17: =IFERROR(_xlfn.XLOOKUP($F17,'FCDB 2017 (full)'!$C:$C,'FCDB 2017 (full)'!$BW:$BW)*$H17/100,0) -> 0 | CG17: =IFERROR(_xlfn.XLOOKUP($F17,'FCDB 2017 (full)'!$C:$C,'FCDB 2017 (full)'!$BX:$BX)*$H17/100,0) -> 0 | CH17: =IFERROR(_xlfn.XLOOKUP($F17,'FCDB 2017 (full)'!$C:$C,'FCDB 2017 (full)'!$BY:$BY)*$H17/100,0) -> 0 | CI17: =IFERROR(_xlfn.XLOOKUP($F17,'FCDB 2017 (full)'!$C:$C,'FCDB 2017 (full)'!$BZ:$BZ)*$H17/100,0) -> 0 | CJ17: =IFERROR(_xlfn.XLOOKUP($F17,'FCDB 2017 (full)'!$C:$C,'FCDB 2017 (full)'!$CA:$CA)*$H17/100,0) -> 0 | CK17: =IFERROR(_xlfn.XLOOKUP($F17,'FCDB 2017 (full)'!$C:$C,'FCDB 2017 (full)'!$CB:$CB)*$H17/100,0) -> 0 | CL17: =IFERROR(_xlfn.XLOOKUP($F17,'FCDB 2017 (full)'!$C:$C,'FCDB 2017 (full)'!$CC:$CC)*$H17/100,0) -> 0 | CM17: =IFERROR(_xlfn.XLOOKUP($F17,'FCDB 2017 (full)'!$C:$C,'FCDB 2017 (full)'!$CD:$CD)*$H17/100,0) -> 0 | CN17: =IFERROR(_xlfn.XLOOKUP($F17,'FCDB 2017 (full)'!$C:$C,'FCDB 2017 (full)'!$CE:$CE)*$H17/100,0) -> 0 | CO17: =IFERROR(_xlfn.XLOOKUP($F17,'FCDB 2017 (full)'!$C:$C,'FCDB 2017 (full)'!$CF:$CF)*$H17/100,0) -> 0 | CP17: =IFERROR(_xlfn.XLOOKUP($F17,'FCDB 2017 (full)'!$C:$C,'FCDB 2017 (full)'!$CG:$CG)*$H17/100,0) -> 0 | CQ17: =IFERROR(_xlfn.XLOOKUP($F17,'FCDB 2017 (full)'!$C:$C,'FCDB 2017 (full)'!$CH:$CH)*$H17/100,0) -> 0 | DA17: SÁNG
